<?xml version="1.0" ?>
<!--
 ...........       ____  _ __
 |  ,-^-,  |      / __ )(_) /_______________ _____  ___
 | (  O  ) |     / __  / / __/ ___/ ___/ __ `/_  / / _ \
 | / ,..´  |    / /_/ / / /_/ /__/ /  / /_/ / / /_/  __/
    +.......   /_____/_/\__/\___/_/   \__,_/ /___/\___/

MIT License

Copyright (c) 2024 Bitcraze
-->

<sdf version="1.8">
  <model name="crazyflie">
    <link name="crazyflie/body">
      <pose> 0 0 17.425E-3 0 0 0</pose>
      <inertial>
        <mass>0.025</mass>
        <inertia>
          <ixx>16.571710E-06</ixx>
          <iyy>16.655602E-06</iyy>
          <izz>29.261652E-06</izz>
          <ixy>0.830806E-06</ixy>
          <ixz>0.718277E-06</ixz>
          <iyz>1.800197E-06</iyz>
        </inertia>
      </inertial>
      <collision name="crazyflie/body_collision">
        <geometry>
          <box>
            <size>0.10 0.10 34.850E-3</size>
          </box>
        </geometry>
      </collision>
      <visual name="crazyflie/body_visual">
        <geometry>
          <mesh>
            <uri>../../../meshes/collada_files/cf2_assembly.dae</uri>
          </mesh>
        </geometry>
      </visual>
      <sensor name='multiranger' type='gpu_lidar'>"
        <pose relative_to='crazyflie/base_link'>0 0 0.1 0 0 0</pose>
        <topic>lidar</topic>
        <update_rate>10</update_rate>
        <ray>
          <scan>
            <horizontal>
                <samples>4</samples>
                <resolution>1</resolution>
                <min_angle>-3.14</min_angle>
                <max_angle>1.57</max_angle>
            </horizontal>
            <vertical>
                <samples>1</samples>
                <resolution>0.01</resolution>
                <min_angle>0</min_angle>
                <max_angle>0</max_angle>
            </vertical>
          </scan>
          <range>
            <min>0.01</min>
            <max>3.49</max>
            <resolution>0.01</resolution>
          </range>
        </ray>
        <always_on>1</always_on>
        <visualize>true</visualize>
      </sensor>
    </link>
    <link name="crazyflie/m1_prop">
      <pose>0.031 -0.031 0.021 0 0 0</pose>
      <inertial>
        <mass>0.0008</mass>
        <inertia>
          <ixx>8.33333E-09</ixx>
          <iyy>1.08333E-07</iyy>
          <izz>1.13333E-07</izz>
        </inertia>
      </inertial>
      <visual name="crazyflie/m1_visual">
        <geometry>
          <mesh>
            <uri>../../../meshes/collada_files/ccw_prop.dae</uri>
          </mesh>
        </geometry>
      </visual>
    </link>
    <link name="crazyflie/m2_prop">
      <pose>-0.031 -0.031 0.021 0 0 0</pose>
      <inertial>
        <mass>0.0008</mass>
        <inertia>
          <ixx>8.33333E-09</ixx>
          <iyy>1.08333E-07</iyy>
          <izz>1.13333E-07</izz>
        </inertia>
      </inertial>
      <visual name="crazyflie/m2_visual">
        <geometry>
          <mesh>
            <uri>../../../meshes/collada_files/cw_prop.dae</uri>
          </mesh>
        </geometry>
      </visual>
    </link>
    <link name="crazyflie/m3_prop">
      <pose>-0.031 0.031 0.021 0 0 0</pose>
      <inertial>
        <mass>0.0008</mass>
        <inertia>
          <ixx>8.33333E-09</ixx>
          <iyy>1.08333E-07</iyy>
          <izz>1.13333E-07</izz>
        </inertia>
      </inertial>
      <visual name="crazyflie/m3_visual">
        <geometry>
          <mesh>
            <uri>../../../meshes/collada_files/ccw_prop.dae</uri>
          </mesh>
        </geometry>
      </visual>
    </link>
    <link name="crazyflie/m4_prop">
      <pose>0.031 0.031 0.021 0 0 0</pose>
      <inertial>
        <mass>0.0008</mass>
        <inertia>
          <ixx>8.33333E-09</ixx>
          <iyy>1.08333E-07</iyy>
          <izz>1.13333E-07</izz>
        </inertia>
      </inertial>
      <visual name="crazyflie/m4_visual">
        <geometry>
          <mesh>
            <uri>../../../meshes/collada_files/cw_prop.dae</uri>
          </mesh>
        </geometry>
      </visual>
    </link>
    <joint name="crazyflie/m1_joint" type="revolute">
      <child>crazyflie/m1_prop</child>
      <parent>crazyflie/body</parent>
      <axis>
        <xyz>0 0 1</xyz>
      </axis>
    </joint>
    <joint name="crazyflie/m2_joint" type="revolute">
      <child>crazyflie/m2_prop</child>
      <parent>crazyflie/body</parent>
      <axis>
        <xyz>0 0 1</xyz>
      </axis>
    </joint>
    <joint name="crazyflie/m3_joint" type="revolute">
      <child>crazyflie/m3_prop</child>
      <parent>crazyflie/body</parent>
      <axis>
        <xyz>0 0 1</xyz>
      </axis>
    </joint>
    <joint name="crazyflie/m4_joint" type="revolute">
      <child>crazyflie/m4_prop</child>
      <parent>crazyflie/body</parent>
      <axis>
        <xyz>0 0 1</xyz>
      </axis>
    </joint>
    <plugin
      filename="gz-sim-multicopter-motor-model-system"
      name="gz::sim::systems::MulticopterMotorModel">
      <robotNamespace>crazyflie</robotNamespace>
      <jointName>crazyflie/m1_joint</jointName>
      <linkName>crazyflie/m1_prop</linkName>
      <turningDirection>ccw</turningDirection>
      <maxRotVelocity>2618</maxRotVelocity>
      <motorConstant>1.28192e-08</motorConstant>
      <momentConstant>0.005964552</momentConstant>
      <rotorDragCoefficient>8.06428e-05</rotorDragCoefficient>
      <rollingMomentCoefficient>0.0000001</rollingMomentCoefficient>
      <rotorVelocitySlowdownSim>20</rotorVelocitySlowdownSim>
      <actuator_number>0</actuator_number>
      <motorType>velocity</motorType>
    </plugin>
    <plugin
      filename="gz-sim-multicopter-motor-model-system"
      name="gz::sim::systems::MulticopterMotorModel">
      <robotNamespace>crazyflie</robotNamespace>
      <jointName>crazyflie/m2_joint</jointName>
      <linkName>crazyflie/m2_prop</linkName>
      <turningDirection>cw</turningDirection>
      <maxRotVelocity>2618</maxRotVelocity>
      <motorConstant>1.28192e-08</motorConstant>
      <momentConstant>0.005964552</momentConstant>
      <rotorDragCoefficient>8.06428e-05</rotorDragCoefficient>
      <rollingMomentCoefficient>0.0000001</rollingMomentCoefficient>
      <rotorVelocitySlowdownSim>20</rotorVelocitySlowdownSim>
      <actuator_number>1</actuator_number>
      <motorType>velocity</motorType>
    </plugin>
    <plugin
      filename="gz-sim-multicopter-motor-model-system"
      name="gz::sim::systems::MulticopterMotorModel">
      <robotNamespace>crazyflie</robotNamespace>
      <jointName>crazyflie/m3_joint</jointName>
      <linkName>crazyflie/m3_prop</linkName>
      <turningDirection>ccw</turningDirection>
      <maxRotVelocity>2618</maxRotVelocity>
      <motorConstant>1.28192e-08</motorConstant>
      <momentConstant>0.005964552</momentConstant>
      <rotorDragCoefficient>8.06428e-05</rotorDragCoefficient>
      <rollingMomentCoefficient>0.0000001</rollingMomentCoefficient>
      <rotorVelocitySlowdownSim>20</rotorVelocitySlowdownSim>
      <actuator_number>2</actuator_number>
      <motorType>velocity</motorType>
    </plugin>
    <plugin
      filename="gz-sim-multicopter-motor-model-system"
      name="gz::sim::systems::MulticopterMotorModel">
      <robotNamespace>crazyflie</robotNamespace>
      <jointName>crazyflie/m4_joint</jointName>
      <linkName>crazyflie/m4_prop</linkName>
      <turningDirection>cw</turningDirection>
      <maxRotVelocity>2618</maxRotVelocity>
      <motorConstant>1.28192e-08</motorConstant>
      <momentConstant>0.005964552</momentConstant>
      <rotorDragCoefficient>8.06428e-05</rotorDragCoefficient>
      <rollingMomentCoefficient>0.0000001</rollingMomentCoefficient>
      <rotorVelocitySlowdownSim>20</rotorVelocitySlowdownSim>
      <actuator_number>3</actuator_number>
      <motorType>velocity</motorType>
    </plugin>
    <plugin
      filename="gz-sim-multicopter-control-system"
      name="gz::sim::systems::MulticopterVelocityControl">
      <robotNamespace>crazyflie</robotNamespace>
      <commandSubTopic>gazebo/command/twist</commandSubTopic>
      <enableSubTopic>enable</enableSubTopic>
      <comLinkName>crazyflie/body</comLinkName>
      <velocityGain>1.25 1.25 0.2425</velocityGain>
      <attitudeGain>0.02 0.02 0.02</attitudeGain>
      <angularRateGain>0.005 0.005 0.005</angularRateGain>
      <rotorConfiguration>
        <rotor>
          <jointName>crazyflie/m1_joint</jointName>
          <forceConstant>1.28192e-08</forceConstant>
          <momentConstant>0.005964552</momentConstant>
          <direction>1</direction>
        </rotor>
        <rotor>
          <jointName>crazyflie/m2_joint</jointName>
          <forceConstant>1.28192e-08</forceConstant>
          <momentConstant>0.005964552</momentConstant>
          <direction>-1</direction>
        </rotor>
        <rotor>
          <jointName>crazyflie/m3_joint</jointName>
          <forceConstant>1.28192e-08</forceConstant>
          <momentConstant>0.005964552</momentConstant>
          <direction>1</direction>
        </rotor>
        <rotor>
          <jointName>crazyflie/m4_joint</jointName>
          <forceConstant>1.28192e-08</forceConstant>
          <momentConstant>0.005964552</momentConstant>
          <direction>-1</direction>
        </rotor>
      </rotorConfiguration>
    </plugin>
    <plugin
      filename="gz-sim-odometry-publisher-system"
      name="gz::sim::systems::OdometryPublisher">
      <dimensions>3</dimensions>
    </plugin>
  </model>
</sdf>